<?xml version="1.0" ?>
<sdf version="1.4">

<!-- TODO

* Update all SDF snippets

-->

  <world name="default">
    <spherical_coordinates>
        <!-- currently gazebo has a bug: instead of outputing lat, long, altitude in ENU
        (x = East, y = North and z = Up) as the default configurations, it's outputting (-E)(-N)U,
        therefore we rotate the default frame 180 so that it would go back to ENU -->
        <heading_deg>180</heading_deg>
    </spherical_coordinates>

    <gui>

     <camera name="user_camera">
       <pose>-4312 3473 5405 0 0.78 -0.71</pose>
     </camera>

      <plugin name='simslides' filename='libsimslides.so'>
        <slide_prefix>roscon-slide</slide_prefix>
        <near_clip>0.1</near_clip>
        <far_clip>50000</far_clip>

        <keyframe type='lookat' number='0'/>

        <keyframe type='stack' number='1'/>

        <keyframe type='stack' number='2'/>

        <keyframe type='stack' number='3'/>

        <keyframe type='stack' number='4'/>

        <keyframe type='lookat' number='5'/>

        <keyframe type='lookat' number='6'/>

        <keyframe type='lookat' number='7'/>

        <keyframe type='stack' number='8'/>

        <keyframe type='stack' number='9'/>

        <keyframe type='lookat' number='10'/>

        <keyframe type='stack' number='110'/>

        <keyframe type='stack' number='111'/>

        <keyframe type='stack' number='120'/>

        <keyframe type='stack' number='121'/>

        <keyframe type='stack' number='122'/>

        <keyframe type='stack' number='123'/>

        <keyframe type='lookat' number='15'/>

        <keyframe type='lookat' number='16'/>

        <keyframe type='stack' number='17'/>

        <keyframe type='stack' number='18'/>

        <keyframe type='stack' number='19'/>

        <keyframe type='stack' number='20'/>

        <keyframe type='lookat' number='21'/>

        <keyframe type='stack' number='22'/>

        <keyframe type='stack' number='23'/>

        <keyframe type='lookat' number='24'/>

        <keyframe type='lookat' number='25'/>

        <keyframe type='lookat' number='26'/>

        <keyframe type='lookat' number='27'/>

        <keyframe type='lookat' number='28'/>

        <keyframe type='stack' number='29'/>

        <keyframe type='stack' number='30'/>

        <keyframe type='stack' number='31'/>

        <keyframe type='stack' number='32'/>

        <keyframe type='stack' number='33'/>

        <keyframe type='cam_pose' pose='-2615.004395 989.036499 -33.712574 0 -0.017604 -0.124844'
            text='<h2>Gazebo ROS camera plugin demo</h2>

<h3>Check camera info</h3>

<p style="color: #222255; font-family: monospace">
ros2 topic echo /gazebo_ros_camera/camera/camera_info
</p>

<h3>Check camera images</h3>

<p style="color: #222255; font-family: monospace">
ros2 run rqt_image_view rqt_image_view /gazebo_ros_camera/camera/image_raw
</p>

<h3>Sensor SDF</h3>

<pre style="color: #222255; font-family: monospace">
<<sensor type="camera" name="camera">>
  <<update_rate>>5<</update_rate>>
  <<visualize>>true<</visualize>>
  <<camera name="camera">>
    <<horizontal_fov>>0.927295218<</horizontal_fov>>
    <<image>>
      <<width>>640<</width>>
      <<height>>480<</height>>
      <<format>>R8G8B8<</format>>
    <</image>>
    <<clip>>
      <<near>>0.02<</near>>
      <<far>>300<</far>>
    <</clip>>
    <<distortion>>
      <<k1>>-0.1<</k1>>
      <<k2>>-0.1<</k2>>
      <<p1>>0<</p1>>
      <<p2>>0<</p2>>
      <<k3>>-0.1<</k3>>
      <<center>>0.5 0.5<</center>>
    <</distortion>>
  <</camera>>
  <<plugin name="camera_controller" filename="libgazebo_ros_camera.so">>
    <<border_crop>>false<</border_crop>>
  <</plugin>>
<</sensor>>
</pre>
'/>

        <keyframe type='cam_pose' pose='-1445.999 1108.47 -14.77 0 0.89 -1.644'
            text='<h2>Gazebo ROS differential drive plugin demo</h2>

<h3>Try sending commands</h3>

<p style="color: #222255; font-family: monospace">
ros2 topic pub /gazebo_ros_diff_drive/cmd_vel geometry_msgs/Twist "{linear: {x: 1.0}}" -1
</p>

<p style="color: #222255; font-family: monospace">
ros2 topic pub /gazebo_ros_diff_drive/cmd_vel geometry_msgs/Twist "{angular: {z: 0.1}}" -1
</p>

<h3>Try listening to odometry</h3>

<p style="color: #222255; font-family: monospace">
ros2 topic echo /gazebo_ros_diff_drive/odom
</p>

<h3>Try listening to TF</h3>

<p style="color: #222255; font-family: monospace">
ros2 run tf2_ros tf2_echo odom chassis
</p>

<p style="color: #222255; font-family: monospace">
ros2 run tf2_ros tf2_echo chassis right_wheel
</p>

<p style="color: #222255; font-family: monospace">
ros2 run tf2_ros tf2_echo chassis left_wheel
</p>

<h3>Model SDF</h3>

<pre style="color: #222255; font-family: monospace">
<<model name="vehicle">>
  <<link name="chassis">>
    <<pose>>-0.151427 -0 0.175 0 -0 0<</pose>>
    <<inertial>>
      <<mass>>1.14395<</mass>>
      <<inertia>>
        <<ixx>>0.126164<</ixx>>
        <<ixy>>0<</ixy>>
        <<ixz>>0<</ixz>>
        <<iyy>>0.416519<</iyy>>
        <<iyz>>0<</iyz>>
        <<izz>>0.481014<</izz>>
      <</inertia>>
    <</inertial>>
    <<visual name="visual">>
      <<geometry>>
        <<box>>
          <<size>>2.01142 1 0.568726<</size>>
        <</box>>
      <</geometry>>
    <</visual>>
    <<collision name="collision">>
      <<geometry>>
        <<box>>
          <<size>>2.01142 1 0.568726<</size>>
        <</box>>
      <</geometry>>
    <</collision>>
  <</link>>

  <<link name="left_wheel">>
    <<pose>>0.554283 0.625029 -0.025 -1.5707 0 0<</pose>>
    <<inertial>>
      <<mass>>2<</mass>>
      <<inertia>>
        <<ixx>>0.145833<</ixx>>
        <<ixy>>0<</ixy>>
        <<ixz>>0<</ixz>>
        <<iyy>>0.145833<</iyy>>
        <<iyz>>0<</iyz>>
        <<izz>>0.125<</izz>>
      <</inertia>>
    <</inertial>>
    <<visual name="visual">>
      <<geometry>>
        <<sphere>>
          <<radius>>0.3<</radius>>
        <</sphere>>
      <</geometry>>
    <</visual>>
    <<collision name="collision">>
      <<geometry>>
        <<sphere>>
          <<radius>>0.3<</radius>>
        <</sphere>>
      <</geometry>>
      <<surface>>
        <<friction>>
          <<ode>>
            <<mu>>1<</mu>>
            <<mu2>>1<</mu2>>
            <<slip1>>0<</slip1>>
            <<slip2>>0<</slip2>>
          <</ode>>
        <</friction>>
        <<contact>>
          <<ode>>
            <<soft_cfm>>0<</soft_cfm>>
            <<soft_erp>>0.2<</soft_erp>>
            <<kp>>1e+13<</kp>>
            <<kd>>1<</kd>>
            <<max_vel>>0.01<</max_vel>>
            <<min_depth>>0.01<</min_depth>>
          <</ode>>
        <</contact>>
      <</surface>>
    <</collision>>
  <</link>>

  <<link name="right_wheel">>
    <<pose>>0.554282 -0.625029 -0.025 -1.5707 0 0<</pose>>
    <<inertial>>
      <<mass>>2<</mass>>
      <<inertia>>
        <<ixx>>0.145833<</ixx>>
        <<ixy>>0<</ixy>>
        <<ixz>>0<</ixz>>
        <<iyy>>0.145833<</iyy>>
        <<iyz>>0<</iyz>>
        <<izz>>0.125<</izz>>
      <</inertia>>
    <</inertial>>
    <<visual name="visual">>
      <<geometry>>
        <<sphere>>
          <<radius>>0.3<</radius>>
        <</sphere>>
      <</geometry>>
    <</visual>>
    <<collision name="collision">>
      <<geometry>>
        <<sphere>>
          <<radius>>0.3<</radius>>
        <</sphere>>
      <</geometry>>
      <<surface>>
        <<friction>>
          <<ode>>
            <<mu>>1<</mu>>
            <<mu2>>1<</mu2>>
            <<slip1>>0<</slip1>>
            <<slip2>>0<</slip2>>
          <</ode>>
        <</friction>>
        <<contact>>
          <<ode>>
            <<soft_cfm>>0<</soft_cfm>>
            <<soft_erp>>0.2<</soft_erp>>
            <<kp>>1e+13<</kp>>
            <<kd>>1<</kd>>
            <<max_vel>>0.01<</max_vel>>
            <<min_depth>>0.01<</min_depth>>
          <</ode>>
        <</contact>>
      <</surface>>
    <</collision>>
  <</link>>

  <<link name="caster">>
    <<pose>>-0.957138 -0 -0.125 0 -0 0<</pose>>
    <<inertial>>
      <<mass>>1<</mass>>
      <<inertia>>
        <<ixx>>0.1<</ixx>>
        <<ixy>>0<</ixy>>
        <<ixz>>0<</ixz>>
        <<iyy>>0.1<</iyy>>
        <<iyz>>0<</iyz>>
        <<izz>>0.1<</izz>>
      <</inertia>>
    <</inertial>>
    <<visual name="visual">>
      <<geometry>>
        <<sphere>>
          <<radius>>0.2<</radius>>
        <</sphere>>
      <</geometry>>
    <</visual>>
    <<collision name="collision">>
      <<geometry>>
        <<sphere>>
          <<radius>>0.2<</radius>>
        <</sphere>>
      <</geometry>>
    <</collision>>
  <</link>>

  <<joint name="left_wheel_joint" type="revolute">>
    <<parent>>chassis<</parent>>
    <<child>>left_wheel<</child>>
    <<axis>>
      <<xyz>>0 0 1<</xyz>>
      <<limit>>
        <<lower>>-1.79769e+308<</lower>>
        <<upper>>1.79769e+308<</upper>>
      <</limit>>
    <</axis>>
  <</joint>>

  <<joint name="right_wheel_joint" type="revolute">>
    <<parent>>chassis<</parent>>
    <<child>>right_wheel<</child>>
    <<axis>>
      <<xyz>>0 0 1<</xyz>>
      <<limit>>
        <<lower>>-1.79769e+308<</lower>>
        <<upper>>1.79769e+308<</upper>>
      <</limit>>
    <</axis>>
  <</joint>>

  <<joint name="caster_wheel" type="ball">>
    <<parent>>chassis<</parent>>
    <<child>>caster<</child>>
  <</joint>>

  <<plugin name="diff_drive" filename="libgazebo_ros_diff_drive.so">>

    <<ros>>
      <<namespace>>/demo<</namespace>>
    <</ros>>

    <<!-- wheels -->>
    <<left_joint>>left_wheel_joint<</left_joint>>
    <<right_joint>>right_wheel_joint<</right_joint>>

    <<!-- kinematics -->>
    <<wheel_separation>>1.25<</wheel_separation>>
    <<wheel_diameter>>0.6<</wheel_diameter>>

    <<!-- limits -->>
    <<max_wheel_torque>>20<</max_wheel_torque>>
    <<max_wheel_acceleration>>1.0<</max_wheel_acceleration>>

    <<!-- output -->>
    <<publish_odom>>true<</publish_odom>>
    <<publish_odom_tf>>true<</publish_odom_tf>>
    <<publish_wheel_tf>>true<</publish_wheel_tf>>

    <<robot_base_frame>>chassis<</robot_base_frame>>

  <</plugin>>

<</model>>
</pre>
'/>

        <keyframe type='cam_pose' pose='-2038.547119 1229.816650 302.064453 0 0.852 1.407999'
            text='<h2>Gazebo ROS video plugin demo</h2>

The visual on top of the box is displaying the images coming from a ROS 2 image topic.

<h3>Visual SDF</h3>

<pre style="color: #222255; font-family: monospace">
<<visual name="visual">>
  <<geometry>>
    <<box>>
      <<size>>0.5 0.5 0.5<</size>>
    <</box>>
  <</geometry>>
  <<plugin name="display_video_controller" filename="libgazebo_ros_video.so">>
    <<ros>>
      <<argument>>~/image_raw:=/camera/image_raw<</argument>>
    <</ros>>
    <<height>>120<</height>>
    <<width>>160<</width>>
  <</plugin>>
<</visual>>
</pre>
'/>

        <keyframe type='lookat' number='34'/>

        <keyframe type='lookat' number='35'/>

        <keyframe type='stack' number='36'/>

        <keyframe type='stack' number='37'/>

        <keyframe type='lookat' number='38'/>

        <keyframe type='lookat' number='39'/>

<!-- Presentation end -->

        <keyframe type='cam_pose' pose='-1440.999 1108.47 -14.77 0 0.89 -1.644'
            text='<h2>Gazebo ROS GPS plugin demo</h2>

<h3>Try for example</h3>

<p style="color: #222255; font-family: monospace">
ros2 topic echo /gazebo_ros_gps_sensor/node/out
</p>

<h3>Sensor SDF</h3>

<pre style="color: #222255; font-family: monospace">
<<sensor name="vehicle_gps" type="gps">>
  <<always_on>>true<</always_on>>
  <<update_rate>>5<</update_rate>>
  <<gps>>
    <<position_sensing>>
      <<horizontal>>
        <<noise type="gaussian">>
          <<mean>>0.0<</mean>>
          <<stddev>>2e-4<</stddev>>
        <</noise>>
      <</horizontal>>
      <<vertical>>
        <<noise type="gaussian">>
          <<mean>>0.0<</mean>>
          <<stddev>>2e-4<</stddev>>
        <</noise>>
      <</vertical>>
    <</position_sensing>>
  <</gps>>
  <<plugin name="ros_publisher" filename="libgazebo_ros_gps_sensor.so">>
    <<ros>>
      <<namespace>>/gps<</namespace>>
      <<argument>>~/out:=data<</argument>>
    <</ros>>
  <</plugin>>
<</sensor>>
</pre>

<h3>Spherical coordinates</h3>

<pre style="color: #222255; font-family: monospace">
<<spherical_coordinates>>
    <<heading_deg>>180<</heading_deg>>
<</spherical_coordinates>>
</pre>
'/>

        <keyframe type='cam_pose' pose='-1435.64 1108.94 -14.94 0 0.74 -1.988'
            text='<h2>Gazebo ROS IMU plugin demo</h2>

<h3>Try for example</h3>

<p style="color: #222255; font-family: monospace">
ros2 topic echo /gazebo_ros_imu_sensor/node/out
</p>

<h3>Sensor SDF</h3>

<pre style="color: #222255; font-family: monospace">
<<sensor name="vehicle_imu" type="imu">>
  <<always_on>>true<</always_on>>
  <<update_rate>>5<</update_rate>>
  <<imu>>
    <<angular_velocity>>
      <<x>>
        <<noise type="gaussian">>
          <<mean>>0.0<</mean>>
          <<stddev>>2e-4<</stddev>>
        <</noise>>
      <</x>>
      <<y>>
        <<noise type="gaussian">>
          <<mean>>0.0<</mean>>
          <<stddev>>2e-4<</stddev>>
        <</noise>>
      <</y>>
      <<z>>
        <<noise type="gaussian">>
          <<mean>>0.0<</mean>>
          <<stddev>>2e-4<</stddev>>
        <</noise>>
      <</z>>
    <</angular_velocity>>
    <<linear_acceleration>>
      <<x>>
        <<noise type="gaussian">>
          <<mean>>0.0<</mean>>
          <<stddev>>1.7e-2<</stddev>>
        <</noise>>
      <</x>>
      <<y>>
        <<noise type="gaussian">>
          <<mean>>0.0<</mean>>
          <<stddev>>1.7e-2<</stddev>>
        <</noise>>
      <</y>>
      <<z>>
        <<noise type="gaussian">>
          <<mean>>0.0<</mean>>
          <<stddev>>1.7e-2<</stddev>>
        <</noise>>
      <</z>>
    <</linear_acceleration>>
  <</imu>>
  <<plugin name="node" filename="libgazebo_ros_imu_sensor.so">>
    <<ros>>
      <<namespace>>/gazebo_ros_imu<</namespace>>
    <</ros>>
  <</plugin>>
<</sensor>>
</pre>
'/>

        <keyframe type='cam_pose' pose='-1430.209229 1108.427246 -15.219577 0 0.736000 -2.108001'
            text='<h2>Gazebo ROS force plugin demo</h2>

<h3>Try for example</h3>

<p style="color: #222255; font-family: monospace">
ros2 topic pub -1 /gazebo_ros_force/gazebo_ros_force geometry_msgs/Wrench "force: {x: 10.0, z: 100.0}"
</p>

<h3>Model SDF</h3>

<pre style="color: #222255; font-family: monospace">
</pre>
'/>

        <keyframe type='cam_pose' pose='-2603.962158 979.824951 -34.316021 0 -0.046 1.039188'
            text='<h2>Gazebo ROS bumper plugin demo</h2>

<h3>Try for example</h3>

<p style="color: #222255; font-family: monospace">
ros2 topic echo /gazebo_ros_bumper/bumper_states
</p>

<h3>Sensor SDF</h3>

<pre style="color: #222255; font-family: monospace">
<<sensor type="contact" name="bumper">>
  <<update_rate>>5<</update_rate>>
  <<contact>>
    <<collision>>collision<</collision>>
  <</contact>>
  <<plugin name="node" filename="libgazebo_ros_bumper.so">>
    <<ros>>
      <<namespace>>/gazebo_ros_bumper<</namespace>>
    <</ros>>
    <<frame_name>>world<</frame_name>>
  <</plugin>>
<</sensor>>
</pre>
'/>

        <keyframe type='cam_pose' pose='1617.726807 1637.341064 48.344860 -0.000001 0.824002 1.120816'
            text='<h2>Gazebo ROS ray plugin demo</h2>

<h3>Try for example</h3>

<p style="color: #222255; font-family: monospace">
ros2 run rviz2 rviz2
</p>

Add the topic <b>/gazebo_ros_ray/node/out</b> and change the
fixed frame to <b>ray_link</b>.

<h3>Sensor SDF</h3>

<pre style="color: #222255; font-family: monospace">
</pre>
'/>

        <keyframe type='cam_pose' pose='736.288 691.55 484.16 0 0.047 -2.59'
            text='<h2>Gazebo ROS joint state publisher plugin demo</h2>

<h3>Try for example</h3>

<p style="color: #222255; font-family: monospace">
ros2 topic echo /gazebo_ros_joint_state_publisher/joint_states
</p>

<h3>Model SDF</h3>

<pre style="color: #222255; font-family: monospace">
</pre>
'/>

        <keyframe type='cam_pose' pose='738.563599 681.777771 484.139069 0 -0.040999 2.729186'
            text='<h2>Gazebo ROS joint pose trajectory plugin demo</h2>

<h3>Try for example</h3>

<p style="color: #222255; font-family: monospace">
ros2 topic pub /gazebo_ros_joint_pose_trajectory/set_joint_trajectory trajectory_msgs/msg/JointTrajectory "{header: {frame_id: world}, joint_names: {upper_joint}, points: [{positions: {0, 0.1, 0.2, 0.3, 0.4, 0.5}}]}"
</p>

<h3>Model SDF</h3>

<pre style="color: #222255; font-family: monospace">
</pre>
'/>

        <keyframe type='cam_pose' pose='5.95337 -5.07052 4.47829 0 0.432748 2.25139'
            text='<h2>Gazebo ROS projector plugin demo</h2>

<h3>Try for example</h3>

Turn it off:

<p style="color: #222255; font-family: monospace">
ros2 topic pub /gazebo_ros_projector/switch std_msgs/msg/Bool "data: false" -1
</p>

<h3>Model SDF</h3>

<pre style="color: #222255; font-family: monospace">
</pre>
'/>

        <keyframe type='cam_pose' pose='1663.378662 1643.339600 29.441582 0 0.464001 2.652001'
            text='<h2>Gazebo ROS planar move plugin demo</h2>

<h3>Try for example</h3>

<p style="color: #222255; font-family: monospace">
ros2 topic pub /gazebo_ros_planar_move/cmd_vel geometry_msgs/Twist "{angular: {z: 0.3}}" -1
</p>

<h3>Model SDF</h3>

<pre style="color: #222255; font-family: monospace">
</pre>
'/>

        <keyframe type='cam_pose' pose='-1458.130371 1069.920898 -33.339748 0 0.13 -2.38'
            text='<h2>Gazebo ROS hand of god plugin demo</h2>

<h3>Try for example</h3>

<p style="color: #222255; font-family: monospace">
ros2 run tf2_ros static_transform_publisher -1467 1065 -35 0 0 1 world link1_desired
</p>

<p style="color: #222255; font-family: monospace">
ros2 run tf2_ros tf2_echo world link1_actual
</p>

<h3>Model SDF</h3>

<pre style="color: #222255; font-family: monospace">
</pre>
'/>

        <keyframe type='cam_pose' pose='-759.972473 492.841339 -30.519588 0 0.01 0.8'
            text='<h2>Gazebo ROS vacuum gripper plugin demo</h2>

<h3>Try for example</h3>

<p style="color: #222255; font-family: monospace">
ros2 service call /gazebo_ros_vacuum_gripper/switch std_srvs/srv/SetBool "{data: True}"
</p>

<p style="color: #222255; font-family: monospace">
ros2 topic echo /gazebo_ros_vacuum_gripper/grasping
</p>

<h3>Model SDF</h3>

<pre style="color: #222255; font-family: monospace">
</pre>
'/>

      </plugin>

      <plugin name='keyboard' filename='libKeyboardGUIPlugin.so'>
      </plugin>

    </gui>

    <scene>
      <sky>
        <clouds>
          <speed>12</speed>
        </clouds>
      </sky>
      <!-- what are good params here? the fog is making the heightmap black near the camera -->
      <!--fog>
        <color>0.8 0.8 0.8 1.0</color>
        <type>linear</type>
        <start>500</start>
        <end>10000</end>
        <density>0.0</density>
      </fog-->
      <grid>false</grid>
      <origin_visual>false</origin_visual>
    </scene>

    <light type="directional" name="sun">
      <pose>0 0 -100 0 0 0</pose>
      <cast_shadows>true</cast_shadows>
      <diffuse>0.9 0.8 0.8 1</diffuse>
      <specular>0.2 0.2 0.2 1</specular>
      <attenuation>
        <range>1000</range>
        <constant>0.9</constant>
        <linear>0.01</linear>
        <quadratic>0.001</quadratic>
      </attenuation>
      <direction>-0.5 0.1 -0.9</direction>
    </light>

     <model name="heightmap">
      <static>true</static>
      <link name="link">
        <visual name="visual_yosemite">
          <geometry>
            <heightmap>
              <texture>
                <diffuse>file://media/textures/yosemite_color.png</diffuse>
                <normal>file://media/materials/textures/flat_normal.png</normal>
                <size>6000</size>
              </texture>
              <uri>file://media/yosemite_elevation.tif</uri>
              <pos>0 0 -1250</pos>
            </heightmap>
          </geometry>
        </visual>
      </link>
    </model>

    <include>
      <name>gazebo_ros_camera</name>
      <pose>
        -2612.518799 987.814453 -33.923840 0 0 -1.798245
      </pose>
      <uri>model://gazebo_ros_camera</uri>
    </include>

    <include>
      <name>gazebo_ros_bumper</name>
      <pose>
        -2603.231934 984.255005 -34.586113 0 0 -0.56
      </pose>
      <uri>model://gazebo_ros_bumper</uri>
    </include>

    <model name="ground_ball">
      <pose>
        -2596 990 -35.8 0 0 0
      </pose>

      <static>true</static>
      <link name="link">
        <visual name="visual">
          <geometry>
            <plane>
              <normal>0 0 1</normal>
              <size>10 10</size>
            </plane>
          </geometry>
          <material>
            <script>
              <uri>file://media/materials/scripts/gazebo.material</uri>
              <name>Gazebo/Residential</name>
            </script>
          </material>
        </visual>
        <collision name="collision">
          <geometry>
            <box><size>10 10 0.001</size></box>
          </geometry>
          <surface>
            <bounce>
              <restitution_coefficient>1.0</restitution_coefficient>
              <threshold>0</threshold>
            </bounce>
            <contact>
              <ode>
                <max_vel>10000</max_vel>
                <min_depth>0.001</min_depth>
              </ode>
            </contact>
          </surface>
        </collision>
      </link>

    </model>

    <model name="ball">
      <pose>
        -2596 990 -30.8 0 0 0
      </pose>
      <allow_auto_disable>false</allow_auto_disable>
      <static>false</static>
      <link name="link">
        <inertial>
          <mass>0.026</mass>
          <!-- inertia based on solid sphere 2/5 mr^2 -->
          <inertia>
            <ixx>1.664e-5</ixx>
            <iyy>1.664e-5</iyy>
            <izz>1.664e-5</izz>
            <ixy>0</ixy>
            <ixz>0</ixz>
            <iyz>0</iyz>
          </inertia>
        </inertial>
        <collision name="collision">
          <geometry>
            <sphere>
              <radius>0.20</radius>
            </sphere>
          </geometry>
          <surface>
            <bounce>
              <restitution_coefficient>10.0</restitution_coefficient>
              <threshold>0</threshold>
            </bounce>
            <contact>
              <ode>
                <max_vel>10000</max_vel>
                <min_depth>0.001</min_depth>
              </ode>
            </contact>
          </surface>
        </collision>
        <visual name="visual">
          <geometry>
            <mesh>
              <scale>0.20 0.20 0.20</scale>
              <uri>model://robocup_3Dsim_ball/meshes/ball.dae</uri>
            </mesh>
          </geometry>
        </visual>
        <sensor type="contact" name="bumper">
          <update_rate>5</update_rate>
          <contact>
            <collision>collision</collision>
          </contact>
          <plugin name="node" filename="libgazebo_ros_bumper.so">
            <ros>
              <namespace>/gazebo_ros_bumper</namespace>
            </ros>
            <frame_name>world</frame_name>
          </plugin>
        </sensor>
      </link>
    </model>

    <model name="camera">
      <pose>-2609.969971 990.691833 -34.168598 0 -0.014000 -0.116813</pose>
      <static>true</static>
      <link name="link">
        <sensor type="camera" name="camera">
          <update_rate>5</update_rate>
          <visualize>true</visualize>
          <camera name="camera">
            <horizontal_fov>0.927295218</horizontal_fov>
            <image>
              <width>640</width>
              <height>480</height>
              <format>R8G8B8</format>
            </image>
            <clip>
              <near>0.02</near>
              <far>5000</far>
            </clip>
            <distortion>
              <k1>-0.3</k1>
              <k2>-0.3</k2>
              <p1>0</p1>
              <p2>0</p2>
              <k3>-0.3</k3>
              <center>0.5 0.5</center>
            </distortion>
          </camera>
          <plugin name="node" filename="libgazebo_ros_camera.so">
            <namespace>/gazebo_ros_camera</namespace>
            <border_crop>true</border_crop>
          </plugin>
        </sensor>
      </link>
    </model>

   <model name="ground_vehicle">
      <pose>
        -1452 1087 -37 0 0 0
      </pose>

      <static>true</static>
      <link name="link">
        <visual name="visual">
          <geometry>
            <plane>
              <normal>0 0 1</normal>
              <size>50 50</size>
            </plane>
          </geometry>
          <material>
            <script>
              <uri>file://media/materials/scripts/gazebo.material</uri>
              <name>Gazebo/Residential</name>
            </script>
          </material>
        </visual>
        <collision name="collision">
          <geometry>
            <box><size>50 50 0.001</size></box>
          </geometry>
          <surface>
            <bounce>
              <restitution_coefficient>1.0</restitution_coefficient>
              <threshold>0</threshold>
            </bounce>
            <contact>
              <ode>
                <max_vel>10000</max_vel>
                <min_depth>0.001</min_depth>
              </ode>
            </contact>
          </surface>
        </collision>
      </link>

    </model>

    <include>
      <name>gazebo_ros_diff_drive</name>
      <pose>-1445.46 1107.2 -16.98 0.805 -0.167 0.12</pose>
      <uri>model://gazebo_ros_diff_drive</uri>
    </include>

    <include>
      <name>gazebo_ros_gps_sensor</name>
      <pose>-1440.46 1107.2 -16.98 0.805 -0.167 0.12</pose>
      <uri>model://gazebo_ros_gps_sensor</uri>
    </include>

    <include>
      <name>gazebo_ros_imu_sensor</name>
      <pose>-1435.45 1107.1999 -16.98 0.805 -0.167 -0.139</pose>
      <uri>model://gazebo_ros_imu_sensor</uri>
    </include>

    <include>
      <name>gazebo_ros_force</name>
      <pose>-1430.45 1107.1999 -16.98 0.805 -0.167 -0.139</pose>
      <uri>model://gazebo_ros_force</uri>
    </include>

    <model name='vehicle'>
      <pose>
        -1452 1087 -36 0 0 0
      </pose>

      <link name='chassis'>
        <pose>-0.151427 -0 0.175 0 -0 0</pose>
        <inertial>
          <mass>1.14395</mass>
          <inertia>
            <ixx>0.126164</ixx>
            <ixy>0</ixy>
            <ixz>0</ixz>
            <iyy>0.416519</iyy>
            <iyz>0</iyz>
            <izz>0.481014</izz>
          </inertia>
        </inertial>
        <visual name='visual'>
          <geometry>
            <box>
              <size>2.01142 1 0.568726</size>
            </box>
          </geometry>
        </visual>
        <collision name='collision'>
          <geometry>
            <box>
              <size>2.01142 1 0.568726</size>
            </box>
          </geometry>
        </collision>
        <sensor name="vehicle_gps" type="gps">
          <always_on>true</always_on>
          <update_rate>5</update_rate>
          <gps>
            <position_sensing>
              <horizontal>
                <noise type="gaussian">
                  <mean>0.0</mean>
                  <stddev>2e-4</stddev>
                </noise>
              </horizontal>
              <vertical>
                <noise type="gaussian">
                  <mean>0.0</mean>
                  <stddev>2e-4</stddev>
                </noise>
              </vertical>
            </position_sensing>
          </gps>
          <plugin name="node" filename="libgazebo_ros_gps_sensor.so">
            <ros>
              <namespace>/gazebo_ros_gps_sensor</namespace>
            </ros>
          </plugin>
        </sensor>
        <sensor name="vehicle_imu" type="imu">
          <always_on>true</always_on>
          <update_rate>5</update_rate>
          <imu>
            <angular_velocity>
              <x>
                <noise type="gaussian">
                  <mean>0.0</mean>
                  <stddev>2e-4</stddev>
                </noise>
              </x>
              <y>
                <noise type="gaussian">
                  <mean>0.0</mean>
                  <stddev>2e-4</stddev>
                </noise>
              </y>
              <z>
                <noise type="gaussian">
                  <mean>0.0</mean>
                  <stddev>2e-4</stddev>
                </noise>
              </z>
            </angular_velocity>
            <linear_acceleration>
              <x>
                <noise type="gaussian">
                  <mean>0.0</mean>
                  <stddev>1.7e-2</stddev>
                </noise>
              </x>
              <y>
                <noise type="gaussian">
                  <mean>0.0</mean>
                  <stddev>1.7e-2</stddev>
                </noise>
              </y>
              <z>
                <noise type="gaussian">
                  <mean>0.0</mean>
                  <stddev>1.7e-2</stddev>
                </noise>
              </z>
            </linear_acceleration>
          </imu>
          <plugin name="node" filename="libgazebo_ros_imu_sensor.so">
            <ros>
              <namespace>/gazebo_ros_imu_sensor</namespace>
            </ros>
          </plugin>
        </sensor>
      </link>

      <link name='left_wheel'>
        <pose>0.554283 0.625029 -0.025 0 0 0</pose>
        <inertial>
          <mass>2</mass>
          <inertia>
            <ixx>0.145833</ixx>
            <ixy>0</ixy>
            <ixz>0</ixz>
            <iyy>0.145833</iyy>
            <iyz>0</iyz>
            <izz>0.125</izz>
          </inertia>
        </inertial>
        <visual name='visual'>
          <geometry>
            <sphere>
              <radius>0.3</radius>
            </sphere>
          </geometry>
        </visual>
        <collision name='collision'>
          <geometry>
            <sphere>
              <radius>0.3</radius>
            </sphere>
          </geometry>
          <surface>
            <friction>
              <ode>
                <mu>1</mu>
                <mu2>1</mu2>
                <slip1>0</slip1>
                <slip2>0</slip2>
              </ode>
            </friction>
            <contact>
              <ode>
                <soft_cfm>0</soft_cfm>
                <soft_erp>0.2</soft_erp>
                <kp>1e+13</kp>
                <kd>1</kd>
                <max_vel>0.01</max_vel>
                <min_depth>0.01</min_depth>
              </ode>
            </contact>
          </surface>
        </collision>
      </link>

      <link name='right_wheel'>
        <pose>0.554282 -0.625029 -0.025 0 0 0</pose>
        <inertial>
          <mass>2</mass>
          <inertia>
            <ixx>0.145833</ixx>
            <ixy>0</ixy>
            <ixz>0</ixz>
            <iyy>0.145833</iyy>
            <iyz>0</iyz>
            <izz>0.125</izz>
          </inertia>
        </inertial>
        <visual name='visual'>
          <geometry>
            <sphere>
              <radius>0.3</radius>
            </sphere>
          </geometry>
        </visual>
        <collision name='collision'>
          <geometry>
            <sphere>
              <radius>0.3</radius>
            </sphere>
          </geometry>
          <surface>
            <friction>
              <ode>
                <mu>1</mu>
                <mu2>1</mu2>
                <slip1>0</slip1>
                <slip2>0</slip2>
              </ode>
            </friction>
            <contact>
              <ode>
                <soft_cfm>0</soft_cfm>
                <soft_erp>0.2</soft_erp>
                <kp>1e+13</kp>
                <kd>1</kd>
                <max_vel>0.01</max_vel>
                <min_depth>0.01</min_depth>
              </ode>
            </contact>
          </surface>
        </collision>
      </link>

      <link name='caster'>
        <pose>-0.957138 -0 -0.125 0 -0 0</pose>
        <inertial>
          <mass>1</mass>
          <inertia>
            <ixx>0.1</ixx>
            <ixy>0</ixy>
            <ixz>0</ixz>
            <iyy>0.1</iyy>
            <iyz>0</iyz>
            <izz>0.1</izz>
          </inertia>
        </inertial>
        <visual name='visual'>
          <geometry>
            <sphere>
              <radius>0.2</radius>
            </sphere>
          </geometry>
        </visual>
        <collision name='collision'>
          <geometry>
            <sphere>
              <radius>0.2</radius>
            </sphere>
          </geometry>
        </collision>
      </link>

      <joint name='left_wheel_joint' type='revolute'>
        <parent>chassis</parent>
        <child>left_wheel</child>
        <axis>
          <xyz>0 1 0</xyz>
          <limit>
            <lower>-1.79769e+308</lower>
            <upper>1.79769e+308</upper>
          </limit>
        </axis>
      </joint>

      <joint name='right_wheel_joint' type='revolute'>
        <parent>chassis</parent>
        <child>right_wheel</child>
        <axis>
          <xyz>0 1 0</xyz>
          <limit>
            <lower>-1.79769e+308</lower>
            <upper>1.79769e+308</upper>
          </limit>
        </axis>
      </joint>

      <joint name='caster_wheel' type='ball'>
        <parent>chassis</parent>
        <child>caster</child>
      </joint>

      <plugin name='node' filename='libgazebo_ros_diff_drive.so'>

        <ros>
          <namespace>/gazebo_ros_diff_drive</namespace>
        </ros>

        <!-- wheels -->
        <left_joint>left_wheel_joint</left_joint>
        <right_joint>right_wheel_joint</right_joint>

        <!-- kinematics -->
        <wheel_separation>1.25</wheel_separation>
        <wheel_diameter>0.6</wheel_diameter>

        <!-- limits -->
        <max_wheel_torque>20</max_wheel_torque>
        <max_wheel_acceleration>1.0</max_wheel_acceleration>

        <!-- output -->
        <publish_odom>true</publish_odom>
        <publish_odom_tf>true</publish_odom_tf>
        <publish_wheel_tf>true</publish_wheel_tf>

        <odometry_frame>odom</odometry_frame>
        <robot_base_frame>chassis</robot_base_frame>

      </plugin>

      <plugin name="force_node" filename="libgazebo_ros_force.so">
        <ros>
          <namespace>/gazebo_ros_force</namespace>
        </ros>
        <link_name>chassis</link_name>
        <force_frame>world</force_frame>
      </plugin>

    </model>

    <include>
      <name>gazebo_ros_planar_move</name>
      <pose>
        1660.254761 1643.660522 27.380943 -0.418935 0 1.255741
      </pose>
      <uri>model://gazebo_ros_planar_move</uri>
    </include>

   <model name="ground_to_move">
      <pose>
        1643 1662 14.5 0 0 0
      </pose>

      <static>true</static>
      <link name="link">
        <visual name="visual">
          <geometry>
            <plane>
              <normal>0 0 1</normal>
              <size>10 10</size>
            </plane>
          </geometry>
          <material>
            <script>
              <uri>file://media/materials/scripts/gazebo.material</uri>
              <name>Gazebo/Residential</name>
            </script>
          </material>
        </visual>
        <collision name="collision">
          <geometry>
            <box><size>10 10 0.001</size></box>
          </geometry>
          <surface>
            <bounce>
              <restitution_coefficient>1.0</restitution_coefficient>
              <threshold>0</threshold>
            </bounce>
            <contact>
              <ode>
                <max_vel>10000</max_vel>
                <min_depth>0.001</min_depth>
              </ode>
            </contact>
          </surface>
        </collision>
      </link>

    </model>

    <model name="model_to_move">
      <pose>
        1643 1662 15 0 0 0
      </pose>
      <link name="link">
        <collision name="collision">
          <geometry>
            <box>
              <size>1 1 1</size>
            </box>
          </geometry>
        </collision>
        <visual name="visual">
          <geometry>
            <box>
              <size>1 1 1</size>
            </box>
          </geometry>
          <material>
            <script>
              <uri>file://media/materials/scripts/gazebo.material</uri>
              <name>Gazebo/Red</name>
            </script>
          </material>
        </visual>
      </link>

      <plugin name='node' filename='libgazebo_ros_planar_move.so'>
        <ros>
          <namespace>/gazebo_ros_planar_move</namespace>
        </ros>

        <update_rate>50</update_rate>
      </plugin>
    </model>

    <include>
      <name>gazebo_ros_hand_of_god</name>
      <pose>
        -1459.442261 1067.954834 -34.122284 0 0 -0.544932
      </pose>
      <uri>model://gazebo_ros_hand_of_god</uri>
    </include>

    <model name="chain">
      <pose>
        -1467.102783 1065.219604 -36.000000 0 0 0
      </pose>
      <link name="canonical">
      </link>
      <link name="link1">
        <pose>0 0 0 -1.5708 0 0</pose>
        <inertial>
          <pose>0 0 0.5 0 0 0</pose>
        </inertial>
        <visual name="visual">
          <pose>0 0 0.5 0 0 0</pose>
          <geometry>
            <cylinder>
              <radius>0.1</radius>
              <length>1.0</length>
            </cylinder>
          </geometry>
          <material>
            <script>
              <uri>file://media/materials/scripts/gazebo.material</uri>
              <name>Gazebo/Yellow</name>
            </script>
          </material>
        </visual>
        <collision name="collision">
          <pose>0 0 0.5 0 0 0</pose>
          <geometry>
            <cylinder>
              <radius>0.1</radius>
              <length>1.0</length>
            </cylinder>
          </geometry>
        </collision>
      </link>
      <link name="link2">
        <pose>0 0.9 0 -1.57 0 0</pose>
        <self_collide>0</self_collide>
        <inertial>
          <pose>0 0 0.5 0 0 0</pose>
        </inertial>
        <visual name="visual">
          <pose>0 0 0.5 0 0 0</pose>
          <geometry>
            <cylinder>
              <radius>0.1</radius>
              <length>1.0</length>
            </cylinder>
          </geometry>
          <material>
            <script>
              <uri>file://media/materials/scripts/gazebo.material</uri>
              <name>Gazebo/Green</name>
            </script>
          </material>
        </visual>
        <collision name="collision">
          <pose>0 0 0.5 0 0 0</pose>
          <geometry>
            <cylinder>
              <radius>0.1</radius>
              <length>1.0</length>
            </cylinder>
          </geometry>
        </collision>
      </link>
      <link name="link3">
        <pose>0 1.8 0 -1.57 0 0</pose>
        <self_collide>0</self_collide>
        <inertial>
          <pose>0 0 0.5 0 0 0</pose>
        </inertial>
        <visual name="visual">
          <pose>0 0 0.5 0 0 0</pose>
          <geometry>
            <cylinder>
              <radius>0.1</radius>
              <length>1.0</length>
            </cylinder>
          </geometry>
          <material>
            <script>
              <uri>file://media/materials/scripts/gazebo.material</uri>
              <name>Gazebo/Blue</name>
            </script>
          </material>
        </visual>
        <collision name="collision">
          <pose>0 0 0.5 0 0 0</pose>
          <geometry>
            <cylinder>
              <radius>0.1</radius>
              <length>1.0</length>
            </cylinder>
          </geometry>
        </collision>
      </link>
      <joint name="joint1" type="revolute">
        <parent>link1</parent>
        <child>link2</child>
        <axis>
          <xyz>1.0 0 0</xyz>
        </axis>
      </joint>
      <joint name="joint2" type="revolute">
        <parent>link2</parent>
        <child>link3</child>
        <axis>
          <xyz>1.0 0 0</xyz>
        </axis>
      </joint>
      <plugin name="node" filename="libgazebo_ros_hand_of_god.so">
        <ros>
          <namespace>/gazebo_ros_hand_of_god</namespace>
        </ros>
        <link_name>link1</link_name>
        <frame_id>link1</frame_id>
      </plugin>

    </model>

    <include>
      <name>gazebo_ros_ray</name>
      <pose>
        1617.659302 1639.073364 46.026249 -0.705770 0.059721 -0.300298
      </pose>
      <uri>model://gazebo_ros_ray</uri>
    </include>

    <model name="ray">
      <pose>
        1638 1667 15 0 0 -0.727
      </pose>
      <static>true</static>
      <link name="ray_link">
        <sensor name="sensor_gpu_ray" type="gpu_ray">
          <pose>0.5 0 0 0 0 0</pose>
          <ray>
            <scan>
              <horizontal>
                <samples>100</samples>
                <resolution>1.0</resolution>
                <min_angle>-1.0</min_angle>
                <max_angle>1.0</max_angle>
              </horizontal>
            </scan>
            <range>
              <min>0.05</min>
              <max>13.0</max>
            </range>
          </ray>
          <always_on>true</always_on>
          <visualize>true</visualize>
          <update_rate>10.0</update_rate>
          <plugin name="node" filename="libgazebo_ros_ray_sensor.so">
            <ros>
              <namespace>/gazebo_ros_ray</namespace>
            </ros>
            <output_type>sensor_msgs/LaserScan</output_type>
          </plugin>
        </sensor>
      </link>
    </model>

    <include>
      <name>gazebo_ros_video</name>
      <pose>-2038.749634 1231.889771 299.570740 -0.4624 0 0.41</pose>
      <uri>model://gazebo_ros_video</uri>
    </include>

    <model name="video">
      <static>true</static>
      <pose>-2037.794067 1231.204712 300.000000 0.305122 0 -0.219313</pose>
      <link name="base_link">
        <visual name="visual">
          <geometry>
            <box>
              <size>0.5 0.5 0.5</size>
            </box>
          </geometry>
          <plugin name="node" filename="libgazebo_ros_video.so">
            <ros>
              <namespace>/gazebo_ros_video</namespace>
              <argument>~/image_raw:=/gazebo_ros_camera/camera/image_raw</argument>
            </ros>
            <height>120</height>
            <width>160</width>
          </plugin>
        </visual>
        <collision name="collision">
          <geometry>
            <box>
              <size>0.5 0.5 0.5</size>
            </box>
          </geometry>
          <laser_retro>100.0</laser_retro>
        </collision>
      </link>
    </model>

    <include>
      <name>gazebo_ros_joint_state_publisher</name>
      <pose>
        732.3853848385847
        690.5387774356643
        483.3511135114346
        0
        0
        -1.3926539623175542
      </pose>
      <uri>model://gazebo_ros_joint_state_publisher</uri>
    </include>

    <include>
      <name>gazebo_ros_joint_pose_trajectory</name>
      <pose>
        735.5
        682.16
        483.69
        0
        0
        -1.956
      </pose>
      <uri>model://gazebo_ros_joint_pose_trajectory</uri>
    </include>

    <model name="pendulum">
      <pose>
        732.69
        687.57
        484.66
        0
        0
        0
      </pose>
      <link name="canonical">
      </link>
      <link name="upper_link">
        <pose>0 0 0 -1.5708 0 0</pose>
        <inertial>
          <pose>0 0 0.5 0 0 0</pose>
        </inertial>
        <visual name="vis_cylinder">
          <pose>0 0 0.5 0 0 0</pose>
          <geometry>
            <cylinder>
              <radius>0.1</radius>
              <length>0.9</length>
            </cylinder>
          </geometry>
          <material>
            <script>
              <uri>file://media/materials/scripts/gazebo.material</uri>
              <name>Gazebo/Yellow</name>
            </script>
          </material>
        </visual>
      </link>
      <link name="lower_link">
        <pose>0.2 0.9 0 -2 0 0</pose>
        <self_collide>0</self_collide>
        <inertial>
          <pose>0 0 0.45 0 0 0</pose>
        </inertial>
        <visual name="vis_cylinder">
          <pose>0 0 0.45 0 0 0</pose>
          <geometry>
            <cylinder>
              <radius>0.1</radius>
              <length>0.9</length>
            </cylinder>
          </geometry>
          <material>
            <script>
              <uri>file://media/materials/scripts/gazebo.material</uri>
              <name>Gazebo/Green</name>
            </script>
          </material>
        </visual>
      </link>
      <joint name="world_joint" type="fixed">
        <parent>world</parent>
        <child>canonical</child>
        <axis>
          <xyz>1.0 0 0</xyz>
        </axis>
      </joint>
      <joint name="upper_joint" type="revolute">
        <parent>canonical</parent>
        <child>upper_link</child>
        <axis>
          <xyz>1.0 0 0</xyz>
        </axis>
      </joint>
      <joint name="lower_joint" type="revolute">
        <parent>upper_link</parent>
        <child>lower_link</child>
        <axis>
          <xyz>1.0 0 0</xyz>
        </axis>
      </joint>
      <plugin name="publisher"
          filename="libgazebo_ros_joint_state_publisher.so">
        <ros>
          <namespace>/gazebo_ros_joint_state_publisher</namespace>
        </ros>
        <update_rate>1</update_rate>
        <joint_name>upper_joint</joint_name>
        <joint_name>lower_joint</joint_name>
      </plugin>
      <plugin name="controller"
          filename="libgazebo_ros_joint_pose_trajectory.so">
        <ros>
          <namespace>/gazebo_ros_joint_pose_trajectory</namespace>
        </ros>
        <update_rate>50</update_rate>
      </plugin>
    </model>


    <model name="projector_model">
      <pose>-1.326927 -0.038119 1.261517 1.570796 0 -0.551969</pose>
      <static>true</static>
      <link name="projector_link">
        <collision name="collision">
          <geometry>
            <sphere>
              <radius>0.1</radius>
            </sphere>
          </geometry>
        </collision>
        <visual name="visual">
          <geometry>
            <sphere>
              <radius>0.1</radius>
            </sphere>
          </geometry>
          <material>
            <script>Gazebo/Grey</script>
          </material>
        </visual>
        <projector name="texture_projector">
          <pose>0 0 0 0 0 0</pose>
          <texture>gazebo_ros_projector/materials/textures/gazebo_ros_projector.png</texture>
          <fov>0.959931088597</fov>
          <near_clip>0.1</near_clip>
          <far_clip>10</far_clip>
        </projector>
      </link>
      <plugin name="node" filename="libgazebo_ros_projector.so">
        <ros>
          <namespace>/gazebo_ros_projector</namespace>
        </ros>
        <projector_link>projector_link</projector_link>
        <projector_name>texture_projector</projector_name>
      </plugin>
    </model>

    <model name='projectee'>
      <static>true</static>
      <pose>1.04 2.9 1.49 0 0 -0.288</pose>
      <link name='link'>
        <visual name='visual'>
          <geometry>
            <box>
              <size>6.4 0.01 5</size>
            </box>
          </geometry>
        </visual>
      </link>
    </model>

    <include>
      <name>gazebo_ros_vacuum_gripper</name>
      <pose>
        -758.465393 495.82 -31.1 0 0 -0.566874
      </pose>
      <uri>model://gazebo_ros_vacuum_gripper</uri>
    </include>

   <model name="ground_vacuum">
      <pose>
        -752 500 -32 0 0 0
      </pose>

      <static>true</static>
      <link name="link">
        <visual name="visual">
          <geometry>
            <plane>
              <normal>0 0 1</normal>
              <size>10 10</size>
            </plane>
          </geometry>
          <material>
            <script>
              <uri>file://media/materials/scripts/gazebo.material</uri>
              <name>Gazebo/Residential</name>
            </script>
          </material>
        </visual>
        <collision name="collision">
          <geometry>
            <box><size>10 10 0.001</size></box>
          </geometry>
          <surface>
            <bounce>
              <restitution_coefficient>1.0</restitution_coefficient>
              <threshold>0</threshold>
            </bounce>
            <contact>
              <ode>
                <max_vel>10000</max_vel>
                <min_depth>0.001</min_depth>
              </ode>
            </contact>
          </surface>
        </collision>
      </link>

    </model>

    <model name='vacuum_gripper'>
      <static>true</static>
      <pose>
        -752 500 -30 0 0 0
      </pose>
      <link name="link">
        <collision name="collision">
          <geometry>
            <cylinder>
              <radius>0.3</radius>
              <length>1</length>
            </cylinder>
          </geometry>
        </collision>
        <visual name="visual">
          <geometry>
            <cylinder>
              <radius>0.3</radius>
              <length>1</length>
            </cylinder>
          </geometry>
          <material>
            <script>
              <uri>file://media/materials/scripts/gazebo.material</uri>
              <name>Gazebo/Orange</name>
            </script>
          </material>
        </visual>
      </link>

      <plugin name='node' filename='libgazebo_ros_vacuum_gripper.so'>

        <ros>
          <namespace>/gazebo_ros_vacuum_gripper</namespace>
        </ros>

        <link_name>link</link_name>

        <max_distance>2.0</max_distance>

        <fixed>ground</fixed>

      </plugin>
    </model>

    <model name='vacuum_grippee'>
      <pose>
        -752 500 -31 0 0 0
      </pose>
      <link name="link1">
        <inertial>
          <mass>0.026</mass>
          <inertia>
            <ixx>1.664e-5</ixx>
            <iyy>1.664e-5</iyy>
            <izz>1.664e-5</izz>
            <ixy>0</ixy>
            <ixz>0</ixz>
            <iyz>0</iyz>
          </inertia>
        </inertial>
        <collision name="collision">
          <geometry>
            <sphere>
              <radius>0.08</radius>
            </sphere>
          </geometry>
        </collision>
        <visual name="visual">
          <geometry>
            <sphere>
              <radius>0.08</radius>
            </sphere>
          </geometry>
        </visual>
      </link>
    </model>



    <!-- slides -->

    <include>
      <name>roscon-slide-0</name>
      <pose>-3000 1132 360 0 0 -1.57</pose>
      <uri>model://roscon-slide-0</uri>
    </include>

    <include>
      <name>roscon-slide-1</name>
      <pose>
        521.3608700353291
        -141.50602061789016
        449.08149189854066
        0
        0
        0.12403624902317523
      </pose>
      <uri>model://roscon-slide-1</uri>
    </include>

    <include>
      <name>roscon-slide-2</name>
      <pose>
        521.3608700353291
        -141.50602061789016
        449.08149189854066
        0
        0
        0.12403624902317523
      </pose>
      <uri>model://roscon-slide-2</uri>
    </include>

    <include>
      <name>roscon-slide-3</name>
      <pose>
        521.3608700353291
        -141.50602061789016
        449.08149189854066
        0
        0
        0.12403624902317523
      </pose>
      <uri>model://roscon-slide-3</uri>
    </include>

    <include>
      <name>roscon-slide-4</name>
      <pose>
        521.3608700353291
        -141.50602061789016
        449.08149189854066
        0
        0
        0.12403624902317523
      </pose>
      <uri>model://roscon-slide-4</uri>
    </include>

    <include>
      <name>roscon-slide-5</name>
      <pose>
        1221.60338357735
        -253.23198568535042
        475.0821126797412
        0
        0
        2.880297471480538
      </pose>
      <uri>model://roscon-slide-5</uri>
    </include>

    <include>
      <name>roscon-slide-6</name>
      <pose>
        1379.737526673402
        -711.0087737625602
        399.96955523500657
        0
        0
        -0.827707907542317
      </pose>
      <uri>model://roscon-slide-6</uri>
    </include>

    <include>
      <name>roscon-slide-7</name>
      <pose>
        1526.7483164192026
        -610.4578887781524
        463.84584030844724
        0
        0
        -2.4366296376714396
      </pose>
      <uri>model://roscon-slide-7</uri>
    </include>

    <include>
      <name>roscon-slide-8</name>
      <pose>
        457.95487745121886
        664.9424021673988
        297.1073330241446
        0
        0
        -1.044702982842486
      </pose>
      <uri>model://roscon-slide-8</uri>
    </include>

    <include>
      <name>roscon-slide-9</name>
      <pose>
        457.95487745121886
        664.9424021673988
        297.1073330241446
        0
        0
        -1.044702982842486
        <!---59.7669981248838
        916.1018999876578
        356.516142235115
        0
        0
        -0.6821379927376277-->
      </pose>
      <uri>model://roscon-slide-9</uri>
    </include>

    <include>
      <name>roscon-slide-10</name>
      <pose>
        -253.374149452962
        387.5088242098959
        466.9171021130408
        0
        0
        2.452053254366553
      </pose>
      <uri>model://roscon-slide-10</uri>
    </include>

    <include>
      <name>roscon-slide-110</name>
      <pose>
        -963.0727111628037
        793.564496990706
        448.74954854257084
        0
        0
        0.5043479672068263
      </pose>
      <uri>model://roscon-slide-11</uri>
    </include>

    <include>
      <name>roscon-slide-111</name>
      <pose>
        -963.0727111628037
        793.564496990706
        448.74954854257084
        0
        0
        0.5043479672068263
        <!---105.7659881325859
        -16.909491218630478
        223.94041971649898
        0
        0
        -0.5119488473838469-->
      </pose>
      <uri>model://roscon-slide-111</uri>
    </include>

    <include>
      <name>roscon-slide-120</name>
      <pose>
        559.8477836860952
        345.59255963237
        193.29410261537714
        0
        0
        -1.0651857368099833
        <!---105.7659881325859
        -16.909491218630478
        223.94041971649898
        0
        0
        -0.5119488473838469-->
      </pose>
      <uri>model://roscon-slide-112</uri>
    </include>

    <include>
      <name>roscon-slide-121</name>
      <pose>
        559.8477836860952
        345.59255963237
        193.29410261537714
        0
        0
        -1.0651857368099833
        <!---105.7659881325859
        -16.909491218630478
        223.94041971649898
        0
        0
        -0.5119488473838469-->
      </pose>
      <uri>model://roscon-slide-12</uri>
    </include>

    <include>
      <name>roscon-slide-122</name>
      <pose>
        559.8477836860952
        345.59255963237
        193.29410261537714
        0
        0
        -1.0651857368099833
      </pose>
      <uri>model://roscon-slide-13</uri>
    </include>

    <include>
      <name>roscon-slide-123</name>
      <pose>
        559.8477836860952
        345.59255963237
        193.29410261537714
        0
        0
        -1.0651857368099833
        <!--410.01034648538825
        397.85696002103737
        359.5466411214914
        0
        0
        -0.925198698701974-->
      </pose>
      <uri>model://roscon-slide-14</uri>
    </include>

    <include>
      <name>roscon-slide-15</name>
      <pose>
        -170.46381859208725
        460.76351514628504
        302.8778121643684
        0
        0
        2.1832500183263557
      </pose>
      <uri>model://roscon-slide-15</uri>
    </include>

    <include>
      <name>roscon-slide-16</name>
      <pose>
        -755.8074652683983
        431.9030928548252
        202.39306617020293
        0
        0
        2.3105155685113132
      </pose>
      <uri>model://roscon-slide-16</uri>
    </include>

    <include>
      <name>roscon-slide-17</name>
      <pose>
        415.0137656986801
        -937.7083310960321
        229.57354644472483
        0
        0
        -2.178944224685889
      </pose>
      <uri>model://roscon-slide-17</uri>
    </include>

    <include>
      <name>roscon-slide-18</name>
      <pose>
        415.0137656986801
        -937.7083310960321
        229.57354644472483
        0
        0
        -2.178944224685889
        <!---304.4647985401406
        378.27767339925845
        403.5677055427936
        0
        0
        -0.038158550003024594-->
      </pose>
      <uri>model://roscon-slide-18</uri>
    </include>

    <include>
      <name>roscon-slide-19</name>
      <pose>
        415.0137656986801
        -937.7083310960321
        229.57354644472483
        0
        0
        -2.178944224685889
        <!--1503.2889874471807
        -688.5876505421245
        462.54894197441536
        0
        0
        -2.6660528908641457-->
      </pose>
      <uri>model://roscon-slide-19</uri>
    </include>

    <include>
      <name>roscon-slide-20</name>
      <pose>
        415.0137656986801
        -937.7083310960321
        229.57354644472483
        0
        0
        -2.178944224685889
        <!--671.94251611089
        281.0605446060058
        468.46717935062065
        0
        0
        0.6294102111524653-->
      </pose>
      <uri>model://roscon-slide-20</uri>
    </include>

    <include>
      <name>roscon-slide-21</name>
      <pose>
        -2.5015657308121035
        -590.1797286811473
        167.70030135449815
        0
        0
        -0.19871080460994328
      </pose>
      <uri>model://roscon-slide-21</uri>
    </include>

    <include>
      <name>roscon-slide-22</name>
      <pose>
        -48.67698167828928
        362.5044427339851
        276.8709643150493
        0
        0
        0.8275339250516129
      </pose>
      <uri>model://roscon-slide-22</uri>
    </include>

    <include>
      <name>roscon-slide-23</name>
      <pose>
        -48.67698167828928
        362.5044427339851
        276.8709643150493
        0
        0
        0.8275339250516129
      </pose>
      <uri>model://roscon-slide-23</uri>
    </include>

    <include>
      <name>roscon-slide-24</name>
      <pose>
        419.2948586255038
        369.943704745423
        228.12699298697683
        0
        0
        -2.3869977804948
      </pose>
      <uri>model://roscon-slide-24</uri>
    </include>

    <include>
      <name>roscon-slide-25</name>
      <pose>
        223.42213793539213
        -530.4794303859449
        431.73738998777714
        0
        0
        1.3708505480569757
      </pose>
      <uri>model://roscon-slide-25</uri>
    </include>

    <include>
      <name>roscon-slide-26</name>
      <pose>
        56.13564046770489
        -291.3382208644233
        440.7157785869824
        0
        0
        2.124605968819557
      </pose>
      <uri>model://roscon-slide-26</uri>
    </include>

    <include>
      <name>roscon-slide-27</name>
      <pose>
        85.39858731688719
        682.2454751376324
        122.09306185177806
        0
        0
        1.7905644906725202
      </pose>
      <uri>model://roscon-slide-27</uri>
    </include>

    <include>
      <name>roscon-slide-28</name>
      <pose>
        -615.4007171796891
        -69.56889711248994
        138.54326775324893
        0
        0
        -1.6940759391897813
      </pose>
      <uri>model://roscon-slide-28</uri>
    </include>

    <include>
      <name>roscon-slide-29</name>
      <pose>
        642.1928494726753
        649.9634533798035
        420.0707030149804
        0
        0
        -0.24444331080469306
      </pose>
      <uri>model://roscon-slide-29</uri>
    </include>

    <include>
      <name>roscon-slide-30</name>
      <pose>
        642.1928494726753
        649.9634533798035
        420.0707030149804
        0
        0
        -0.24444331080469306
      </pose>
      <uri>model://roscon-slide-30</uri>
    </include>

    <include>
      <name>roscon-slide-31</name>
      <pose>
        642.1928494726753
        649.9634533798035
        420.0707030149804
        0
        0
        -0.24444331080469306
      </pose>
      <uri>model://roscon-slide-31</uri>
    </include>

    <include>
      <name>roscon-slide-32</name>
      <pose>
        642.1928494726753
        649.9634533798035
        420.0707030149804
        0
        0
        -0.24444331080469306
      </pose>
      <uri>model://roscon-slide-32</uri>
    </include>

    <include>
      <name>roscon-slide-33</name>
      <pose>
        642.1928494726753
        649.9634533798035
        420.0707030149804
        0
        0
        -0.24444331080469306
      </pose>
      <uri>model://roscon-slide-33</uri>
    </include>

    <include>
      <name>roscon-slide-34</name>
      <pose>
        -473.5748575576047
        405.58715379724595
        278.40537728335096
        0
        0
        -2.8032966892640965
      </pose>
      <uri>model://roscon-slide-34</uri>
    </include>

    <include>
      <name>roscon-slide-35</name>
      <pose>
        -577.95524348239
        -347.98939676056966
        345.9137455356556
        0
        0
        -1.1646783259607798
      </pose>
      <uri>model://roscon-slide-35</uri>
    </include>

    <include>
      <name>roscon-slide-36</name>
      <pose>
        -449.5713015419551
        100.11364847261098
        188.87493776954113
        0
        0
        2.9442795649913824
      </pose>
      <uri>model://roscon-slide-36</uri>
    </include>

    <include>
      <name>roscon-slide-37</name>
      <pose>
        -449.5713015419551
        100.11364847261098
        188.87493776954113
        0
        0
        2.9442795649913824
      </pose>
      <uri>model://roscon-slide-37</uri>
    </include>

    <include>
      <name>roscon-slide-38</name>
      <pose>
        178.8654398585336
        920.0259297191844
        188.7472876374677
        0
        0
        1.7539225582250975
      </pose>
      <uri>model://roscon-slide-38</uri>
    </include>

    <include>
      <name>roscon-slide-39</name>
      <pose>
        477.0356857090277
        -622.354166921547
        497.5959918110286
        0
        0
        -0.24981913046026705
      </pose>
      <uri>model://roscon-slide-39</uri>
    </include>

  </world>
</sdf>
